Workbook
Name IQ_CH: 110000
Name IQ_CQ: 5000
Name IQ_CY: 10000
Name IQ_DAILY: 500000
Name IQ_FH: 100000
Name IQ_FQ: 500
Name IQ_FY: 1000
Name IQ_LTM: 2000
Name IQ_MONTH: 15000
Name IQ_NTM: 6000
Name IQ_WEEK: 50000
Name IQ_YTD: 3000

Sheet 3S
B1: RMB’000 | C1: 人民币(千元) | D1: 2022 | E1: 2023 | F1: 2024 | G1: 2025 | H1: 2026 | I1: 2027 | J1: 2028 | L1: 1Q25 | M1: 2Q25 | N1: 3Q25 | O1: 4Q25 | P1: 1Q26 | Q1: 2Q26 | R1: 3Q26 | S1: 4Q26E | U1: 1H25 | V1: 1H26 | X1: 9M25 | Y1: 9M26
D2: ACT实际 | E2: ACT实际 | F2: ACT实际 | G2: ACT实际 | H2: EST预测 | I2: EST预测 | J2: EST预测 | L2: ACT实际 | M2: ACT实际 | N2: ACT实际 | O2: ACT实际 | P2: ACT实际 | Q2: ACT实际 | R2: ACT实际 | S2: EST预测 | U2: ACT实际 | V2: ACT实际 | X2: ACT实际 | Y2: ACT实际
B3: Income Statement | C3: 收益表
B4: Operating income | C4: 营业收入 | H4: =Y4+S4 -> 0 | I4: ='Revenue Projection'!H12*100000 -> 0 | J4: ='Revenue Projection'!I12*100000 -> 0 | S4: ='Revenue Projection'!R12*100000 -> 0
B5: yoy growth (%) | C5: 同比增长（%） | E5: =E4/D4-1 -> #DIV/0! | F5: =F4/E4-1 -> #DIV/0! | G5: =G4/F4-1 -> #DIV/0! | H5: =H4/G4-1 -> #DIV/0! | I5: =I4/H4-1 -> #DIV/0! | J5: =J4/I4-1 -> #DIV/0! | P5: =P4/L4-1 -> #DIV/0! | Q5: =Q4/M4-1 -> #DIV/0! | R5: =R4/N4-1 -> #DIV/0! | S5: =S4/O4-1 -> #DIV/0! | V5: =V4/U4-1 -> #DIV/0! | Y5: =Y4/X4-1 -> #DIV/0!
B6: Operating costs | C6: 营业成本 | H6: =Y6+S6 -> 0 | I6: =-'Revenue Projection'!H35*100000 -> 0 | J6: =-'Revenue Projection'!I35*100000 -> 0 | S6: =-'Revenue Projection'!R35*100000 -> 0
B7: Gross profit | C7: 毛利 | D7: =D4+D6 -> 0 | E7: =E4+E6 -> 0 | F7: =F4+F6 -> 0 | G7: =G4+G6 -> 0 | H7: =H4+H6 -> 0 | I7: =I4+I6 -> 0 | J7: =J4+J6 -> 0 | L7: =L4+L6 -> 0 | M7: =M4+M6 -> 0 | N7: =N4+N6 -> 0 | O7: =O4+O6 -> 0 | P7: =P4+P6 -> 0 | Q7: =Q4+Q6 -> 0 | R7: =R4+R6 -> 0 | S7: =S4+S6 -> 0 | U7: =U4+U6 -> 0 | V7: =V4+V6 -> 0 | X7: =X4+X6 -> 0 | Y7: =Y4+Y6 -> 0
B8: GPM (%) | C8: 毛利率（%） | D8: =D7/D4 -> #DIV/0! | E8: =E7/E4 -> #DIV/0! | F8: =F7/F4 -> #DIV/0! | G8: =G7/G4 -> #DIV/0! | H8: =H7/H4 -> #DIV/0! | I8: =I7/I4 -> #DIV/0! | J8: =J7/J4 -> #DIV/0! | L8: =L7/L4 -> #DIV/0! | M8: =M7/M4 -> #DIV/0! | N8: =N7/N4 -> #DIV/0! | O8: =O7/O4 -> #DIV/0! | P8: =P7/P4 -> #DIV/0! | Q8: =Q7/Q4 -> #DIV/0! | R8: =R7/R4 -> #DIV/0! | S8: =S7/S4 -> #DIV/0! | U8: =U7/U4 -> #DIV/0! | V8: =V7/V4 -> #DIV/0! | X8: =X7/X4 -> #DIV/0! | Y8: =Y7/Y4 -> #DIV/0!
B10: Tax expense & others | C10: 税金及附加 | H10: =Y10+S10 -> #DIV/0! | I10: =-I11*I4 -> #DIV/0! | J10: =-J11*J4 -> #DIV/0! | S10: =O10/O4*S4 -> #DIV/0!
B11: as a % of revenue | C11: 对比收入 | D11: =-D10/D4 -> #DIV/0! | E11: =-E10/E4 -> #DIV/0! | F11: =-F10/F4 -> #DIV/0! | G11: =-G10/G4 -> #DIV/0! | H11: =-H10/H4 -> #DIV/0! | I11: =H11 -> #DIV/0! | J11: =I11 -> #DIV/0! | L11: =-L10/L4 -> #DIV/0! | M11: =-M10/M4 -> #DIV/0! | N11: =-N10/N4 -> #DIV/0! | O11: =-O10/O4 -> #DIV/0! | P11: =-P10/P4 -> #DIV/0! | Q11: =-Q10/Q4 -> #DIV/0! | R11: =-R10/R4 -> #DIV/0! | S11: =-S10/S4 -> #DIV/0! | U11: =-U10/U4 -> #DIV/0! | V11: =-V10/V4 -> #DIV/0! | X11: =-X10/X4 -> #DIV/0! | Y11: =-Y10/Y4 -> #DIV/0!
B12: Selling and distribution expenses | C12: 销售费用 | H12: =Y12+S12 -> #DIV/0! | I12: =-I13*I4 -> #DIV/0! | J12: =-J13*J4 -> #DIV/0! | S12: =O12/O4*S4 -> #DIV/0!
B13: as a % of revenue | C13: 对比收入 | D13: =-D12/D4 -> #DIV/0! | E13: =-E12/E4 -> #DIV/0! | F13: =-F12/F4 -> #DIV/0! | G13: =-G12/G4 -> #DIV/0! | H13: =-H12/H4 -> #DIV/0! | I13: =H13 -> #DIV/0! | J13: =I13 -> #DIV/0! | L13: =-L12/L4 -> #DIV/0! | M13: =-M12/M4 -> #DIV/0! | N13: =-N12/N4 -> #DIV/0! | O13: =-O12/O4 -> #DIV/0! | P13: =-P12/P4 -> #DIV/0! | Q13: =-Q12/Q4 -> #DIV/0! | R13: =-R12/R4 -> #DIV/0! | S13: =-S12/S4 -> #DIV/0! | U13: =-U12/U4 -> #DIV/0! | V13: =-V12/V4 -> #DIV/0! | X13: =-X12/X4 -> #DIV/0! | Y13: =-Y12/Y4 -> #DIV/0!
B14: Administrative expenses | C14: 管理费用 | H14: =Y14+S14 -> #DIV/0! | I14: =-I15*I4 -> #DIV/0! | J14: =-J15*J4 -> #DIV/0! | S14: =O14/O4*S4 -> #DIV/0!
B15: as a % of revenue | C15: 对比收入 | D15: =-D14/D4 -> #DIV/0! | E15: =-E14/E4 -> #DIV/0! | F15: =-F14/F4 -> #DIV/0! | G15: =-G14/G4 -> #DIV/0! | H15: =-H14/H4 -> #DIV/0! | I15: =H15 -> #DIV/0! | J15: =I15 -> #DIV/0! | L15: =-L14/L4 -> #DIV/0! | M15: =-M14/M4 -> #DIV/0! | N15: =-N14/N4 -> #DIV/0! | O15: =-O14/O4 -> #DIV/0! | P15: =-P14/P4 -> #DIV/0! | Q15: =-Q14/Q4 -> #DIV/0! | R15: =-R14/R4 -> #DIV/0! | S15: =-S14/S4 -> #DIV/0! | U15: =-U14/U4 -> #DIV/0! | V15: =-V14/V4 -> #DIV/0! | X15: =-X14/X4 -> #DIV/0! | Y15: =-Y14/Y4 -> #DIV/0!
B16: R&D expenses | C16: 研发费用 | H16: =Y16+S16 -> #DIV/0! | I16: =-I17*I4 -> #DIV/0! | J16: =-J17*J4 -> #DIV/0! | S16: =O16/O4*S4 -> #DIV/0!
B17: as a % of revenue | C17: 对比收入 | D17: =-D16/D4 -> #DIV/0! | E17: =-E16/E4 -> #DIV/0! | F17: =-F16/F4 -> #DIV/0! | G17: =-G16/G4 -> #DIV/0! | H17: =-H16/H4 -> #DIV/0! | I17: =H17 -> #DIV/0! | J17: =I17 -> #DIV/0! | L17: =-L16/L4 -> #DIV/0! | M17: =-M16/M4 -> #DIV/0! | N17: =-N16/N4 -> #DIV/0! | O17: =-O16/O4 -> #DIV/0! | P17: =-P16/P4 -> #DIV/0! | Q17: =-Q16/Q4 -> #DIV/0! | R17: =-R16/R4 -> #DIV/0! | S17: =-S16/S4 -> #DIV/0! | U17: =-U16/U4 -> #DIV/0! | V17: =-V16/V4 -> #DIV/0! | X17: =-X16/X4 -> #DIV/0! | Y17: =-Y16/Y4 -> #DIV/0!
B18: Finance income, net | C18: 财务收入（费用） | H18: =Y18+S18 -> 0 | I18: =I231 -> #DIV/0! | J18: =J231 -> #DIV/0! | S18: =Y18/3 -> 0
B19: as a % of revenue | C19: 对比收入 | D19: =D18/D4 -> #DIV/0! | E19: =E18/E4 -> #DIV/0! | F19: =F18/F4 -> #DIV/0! | G19: =G18/G4 -> #DIV/0! | H19: =H18/H4 -> #DIV/0! | I19: =I18/I4 -> #DIV/0! | J19: =J18/J4 -> #DIV/0! | L19: =L18/L4 -> #DIV/0! | M19: =M18/M4 -> #DIV/0! | N19: =N18/N4 -> #DIV/0! | O19: =O18/O4 -> #DIV/0! | P19: =P18/P4 -> #DIV/0! | Q19: =Q18/Q4 -> #DIV/0! | R19: =R18/R4 -> #DIV/0! | S19: =S18/S4 -> #DIV/0! | U19: =U18/U4 -> #DIV/0! | V19: =V18/V4 -> #DIV/0! | X19: =X18/X4 -> #DIV/0! | Y19: =Y18/Y4 -> #DIV/0!
B20: Other income | C20: 其他收益 | H20: =Y20+S20 -> 0 | I20: =-I21*I4 -> #DIV/0! | J20: =-J21*J4 -> #DIV/0! | S20: =Y20/3 -> 0
B21: as a % of revenue | C21: 对比收入 | D21: =D20/D4 -> #DIV/0! | E21: =E20/E4 -> #DIV/0! | F21: =F20/F4 -> #DIV/0! | G21: =G20/G4 -> #DIV/0! | H21: =H20/H4 -> #DIV/0! | I21: =H21 -> #DIV/0! | J21: =I21 -> #DIV/0! | L21: =L20/L4 -> #DIV/0! | M21: =M20/M4 -> #DIV/0! | N21: =N20/N4 -> #DIV/0! | O21: =O20/O4 -> #DIV/0! | P21: =P20/P4 -> #DIV/0! | Q21: =Q20/Q4 -> #DIV/0! | R21: =R20/R4 -> #DIV/0! | S21: =S20/S4 -> #DIV/0! | U21: =U20/U4 -> #DIV/0! | V21: =V20/V4 -> #DIV/0! | X21: =X20/X4 -> #DIV/0! | Y21: =Y20/Y4 -> #DIV/0!
B22: Non-operating income, net | C22: 净营业外收入 | H22: =Y22+S22 -> 0 | I22: =-I23*I4 -> #DIV/0! | J22: =-J23*J4 -> #DIV/0! | S22: =O22 -> 0
B23: as a % of revenue | C23: 对比收入 | D23: =-D22/D4 -> #DIV/0! | E23: =-E22/E4 -> #DIV/0! | F23: =-F22/F4 -> #DIV/0! | G23: =G22/G4 -> #DIV/0! | H23: =H22/H4 -> #DIV/0! | I23: =H23 -> #DIV/0! | J23: =I23 -> #DIV/0! | L23: =-L22/L4 -> #DIV/0! | M23: =-M22/M4 -> #DIV/0! | N23: =-N22/N4 -> #DIV/0! | O23: =-O22/O4 -> #DIV/0! | P23: =-P22/P4 -> #DIV/0! | Q23: =-Q22/Q4 -> #DIV/0! | R23: =-R22/R4 -> #DIV/0! | S23: =-S22/S4 -> #DIV/0! | U23: =-U22/U4 -> #DIV/0! | V23: =-V22/V4 -> #DIV/0! | X23: =-X22/X4 -> #DIV/0! | Y23: =-Y22/Y4 -> #DIV/0!
B25: EBITDA | C25: EBITDA | D25: =D7+D12+D14+D27+D10+D16 -> 0 | E25: =E7+E12+E14+E27+E10+E16 -> 0 | F25: =F7+F12+F14+F27+F10+F16 -> 0 | G25: =G7+G12+G14+G27+G10+G16 -> 0 | H25: =H7+H12+H14+H27+H10+H16 -> #DIV/0! | I25: =I7+I12+I14+I27+I10+I16 -> #DIV/0! | J25: =J7+J12+J14+J27+J10+J16 -> #DIV/0! | L25: =L7+L12+L14+L27 -> 0 | M25: =M7+M12+M14+M27 -> 0 | N25: =N7+N12+N14+N27 -> 0 | O25: =O7+O12+O14+O27 -> 0 | P25: =P7+P12+P14+P27 -> 0 | Q25: =Q7+Q12+Q14+Q27 -> 0 | R25: =R7+R12+R14+R27 -> 0 | S25: =S7+S12+S14+S27 -> #DIV/0! | U25: =U7+U12+U14+U27 -> 0 | V25: =V7+V12+V14+V27 -> 0 | X25: =X7+X12+X14+X27 -> 0 | Y25: =Y7+Y12+Y14+Y27 -> 0
B26: EBITDA margin % | C26: EBITDA 利润率 % | D26: =D25/D4 -> #DIV/0! | E26: =E25/E4 -> #DIV/0! | F26: =F25/F4 -> #DIV/0! | G26: =G25/G4 -> #DIV/0! | H26: =H25/H4 -> #DIV/0! | I26: =I25/I4 -> #DIV/0! | J26: =J25/J4 -> #DIV/0! | L26: =L25/L4 -> #DIV/0! | M26: =M25/M4 -> #DIV/0! | N26: =N25/N4 -> #DIV/0! | O26: =O25/O4 -> #DIV/0! | P26: =P25/P4 -> #DIV/0! | Q26: =Q25/Q4 -> #DIV/0! | R26: =R25/R4 -> #DIV/0! | S26: =S25/S4 -> #DIV/0! | U26: =U25/U4 -> #DIV/0! | V26: =V25/V4 -> #DIV/0! | X26: =X25/X4 -> #DIV/0! | Y26: =Y25/Y4 -> #DIV/0!
B27: Depreciation | C27: 折旧 | D27: =SUM(D28:D30) -> 0 | E27: =SUM(E28:E30) -> 0 | F27: =SUM(F28:F30) -> 0 | G27: =SUM(G28:G30) -> 0 | H27: =SUM(H28:H30) -> #DIV/0! | I27: =SUM(I28:I30) -> #DIV/0! | J27: =SUM(J28:J30) -> #DIV/0! | L27: =SUM(L28:L30) -> 0 | M27: =SUM(M28:M30) -> 0 | N27: =SUM(N28:N30) -> 0 | O27: =SUM(O28:O30) -> 0 | P27: =SUM(P28:P30) -> 0 | Q27: =SUM(Q28:Q30) -> 0 | R27: =SUM(R28:R30) -> 0 | S27: =SUM(S28:S30) -> 0 | U27: =SUM(U28:U30) -> 0 | V27: =SUM(V28:V30) -> 0 | X27: =SUM(X28:X30) -> 0 | Y27: =SUM(Y28:Y30) -> 0
B28: PPE | C28: 固定资产 | H28: =H67 -> #DIV/0! | I28: =I67 -> #DIV/0! | J28: =J67 -> #DIV/0!
B29: Right-of-use assets | C29: 使用权资产 | H29: =H68 -> #DIV/0! | I29: =I68 -> #DIV/0! | J29: =J68 -> #DIV/0!
B30: Amortisation of other intangible assets | C30: 其他无形资产摊销 | H30: =H69 -> #DIV/0! | I30: =I69 -> #DIV/0! | J30: =J69 -> #DIV/0!
B32: Profit before taxation | C32: 除稅前溢利 | D32: =D7+D10+D12+D14+D16+D18+D20+D22 -> 0 | E32: =E7+E10+E12+E14+E16+E18+E20+E22 -> 0 | F32: =F7+F10+F12+F14+F16+F18+F20+F22 -> 0 | G32: =G7+G10+G12+G14+G16+G18+G20+G22 -> 0 | H32: =H7+H10+H12+H14+H16+H18+H20+H22 -> #DIV/0! | I32: =I7+I10+I12+I14+I16+I18+I20+I22 -> #DIV/0! | J32: =J7+J10+J12+J14+J16+J18+J20+J22 -> #DIV/0! | L32: =L7+L10+L12+L14+L16+L18+L20+L22 -> 0 | M32: =M7+M10+M12+M14+M16+M18+M20+M22 -> 0 | N32: =N7+N10+N12+N14+N16+N18+N20+N22 -> 0 | O32: =O7+O10+O12+O14+O16+O18+O20+O22 -> 0 | P32: =P7+P10+P12+P14+P16+P18+P20+P22 -> 0 | Q32: =Q7+Q10+Q12+Q14+Q16+Q18+Q20+Q22 -> 0 | R32: =R7+R10+R12+R14+R16+R18+R20+R22 -> 0 | S32: =S7+S10+S12+S14+S16+S18+S20+S22 -> #DIV/0! | U32: =U7+U10+U12+U14+U16+U18+U20+U22 -> 0 | V32: =V7+V10+V12+V14+V16+V18+V20+V22 -> 0 | X32: =X7+X10+X12+X14+X16+X18+X20+X22 -> 0 | Y32: =Y7+Y10+Y12+Y14+Y16+Y18+Y20+Y22 -> 0
B33: Income tax expense | C33: 所得稅開支 | H33: =Y33+S33 -> #DIV/0! | I33: =-I32*I34 -> #DIV/0! | J33: =-J32*J34 -> #DIV/0! | S33: =-H34*H32-Y33 -> #DIV/0!
B34: Effective tax rate (%) | C34: 税率（%） | D34: =-D33/(D32) -> #DIV/0! | E34: =-E33/(E32) -> #DIV/0! | F34: =-F33/(F32) -> #DIV/0! | G34: =-G33/(G32) -> #DIV/0! | H34: =G34 -> #DIV/0! | I34: =H34 -> #DIV/0! | J34: =I34 -> #DIV/0! | L34: =-L33/(L32) -> #DIV/0! | M34: =-M33/(M32) -> #DIV/0! | N34: =-N33/(N32) -> #DIV/0! | O34: =-O33/(O32) -> #DIV/0! | P34: =-P33/(P32) -> #DIV/0! | Q34: =-Q33/(Q32) -> #DIV/0! | R34: =-R33/(R32) -> #DIV/0! | S34: =-S33/(S32) -> #DIV/0! | U34: =-U33/(U32) -> #DIV/0! | V34: =-V33/(V32) -> #DIV/0! | X34: =-X33/(X32) -> #DIV/0! | Y34: =-Y33/(Y32) -> #DIV/0!
B36: Profit after taxation | C36: 除稅後溢利 | D36: =SUM(D32:D33) -> 0 | E36: =SUM(E32:E33) -> 0 | F36: =SUM(F32:F33) -> 0 | G36: =SUM(G32:G33) -> 0 | H36: =SUM(H32:H33) -> #DIV/0! | I36: =SUM(I32:I33) -> #DIV/0! | J36: =SUM(J32:J33) -> #DIV/0! | L36: =SUM(L32:L33) -> 0 | M36: =SUM(M32:M33) -> 0 | N36: =SUM(N32:N33) -> 0 | O36: =SUM(O32:O33) -> 0 | P36: =SUM(P32:P33) -> 0 | Q36: =SUM(Q32:Q33) -> 0 | R36: =SUM(R32:R33) -> 0 | S36: =SUM(S32:S33) -> #DIV/0! | U36: =SUM(U32:U33) -> 0 | V36: =SUM(V32:V33) -> 0 | X36: =SUM(X32:X33) -> 0 | Y36: =SUM(Y32:Y33) -> 0
B37: Equity shareholders of the Company | C37: 本公司權益持有人 | H37: =Y37+S37 -> #DIV/0! | I37: =I36-I40 -> #DIV/0! | J37: =J36-J40 -> #DIV/0! | S37: =S36-S40 -> #DIV/0!
B38: yoy growth (%) | C38: 同比增长（%） | E38: =E37/D37-1 -> #DIV/0! | F38: =F37/E37-1 -> #DIV/0! | G38: =G37/F37-1 -> #DIV/0! | H38: =H37/G37-1 -> #DIV/0! | I38: =I37/H37-1 -> #DIV/0! | J38: =J37/I37-1 -> #DIV/0! | P38: =P37/L37-1 -> #DIV/0! | Q38: =Q37/M37-1 -> #DIV/0! | R38: =R37/N37-1 -> #DIV/0! | S38: =S37/O37-1 -> #DIV/0! | V38: =V37/U37-1 -> #DIV/0! | Y38: =Y37/X37-1 -> #DIV/0!
B39: net margin (%) | C39: 净利润率（%） | D39: =D37/D4 -> #DIV/0! | E39: =E37/E4 -> #DIV/0! | F39: =F37/F4 -> #DIV/0! | G39: =G37/G4 -> #DIV/0! | H39: =H37/H4 -> #DIV/0! | I39: =I37/I4 -> #DIV/0! | J39: =J37/J4 -> #DIV/0! | L39: =L37/L4 -> #DIV/0! | M39: =M37/M4 -> #DIV/0! | N39: =N37/N4 -> #DIV/0! | O39: =O37/O4 -> #DIV/0! | P39: =P37/P4 -> #DIV/0! | Q39: =Q37/Q4 -> #DIV/0! | R39: =R37/R4 -> #DIV/0! | S39: =S37/S4 -> #DIV/0! | U39: =U37/U4 -> #DIV/0! | V39: =V37/V4 -> #DIV/0! | X39: =X37/X4 -> #DIV/0! | Y39: =Y37/Y4 -> #DIV/0!
B40: Non-controlling interests | C40: 非控股權益 | D40: =D36-D37 -> 0 | E40: =E36-E37 -> 0 | F40: =F36-F37 -> 0 | G40: =G36-G37 -> 0 | H40: =Y40+S40 -> #DIV/0! | I40: =I36*I41 -> #DIV/0! | J40: =J36*J41 -> #DIV/0! | L40: =L36-L37 -> 0 | M40: =M36-M37 -> 0 | N40: =N36-N37 -> 0 | O40: =O36-O37 -> 0 | P40: =P36-P37 -> 0 | Q40: =Q36-Q37 -> 0 | R40: =R36-R37 -> 0 | S40: =S36*S41 -> #DIV/0! | U40: =U36-U37 -> 0 | V40: =V36-V37 -> 0 | X40: =X36-X37 -> 0 | Y40: =Y36-Y37 -> 0
D41: =D40/D36 -> #DIV/0! | E41: =E40/E36 -> #DIV/0! | F41: =F40/F36 -> #DIV/0! | G41: =G40/G36 -> #DIV/0! | H41: =H40/H36 -> #DIV/0! | I41: =H41 -> #DIV/0! | J41: =I41 -> #DIV/0! | L41: =L40/L36 -> #DIV/0! | M41: =M40/M36 -> #DIV/0! | N41: =N40/N36 -> #DIV/0! | O41: =O40/O36 -> #DIV/0! | P41: =P40/P36 -> #DIV/0! | Q41: =Q40/Q36 -> #DIV/0! | R41: =R40/R36 -> #DIV/0! | S41: =Y41 -> #DIV/0! | U41: =U40/U36 -> #DIV/0! | V41: =V40/V36 -> #DIV/0! | X41: =X40/X36 -> #DIV/0! | Y41: =Y40/Y36 -> #DIV/0!
B43: Weighted average no. of shares (million) | C43: 摊薄后股数（百万股） | H43: =G43 -> 0 | I43: =H43 -> 0 | J43: =I43 -> 0
B44: EPS | C44: 每股收益 | D44: =D37/(D43*1000) -> #DIV/0! | E44: =E37/(E43*1000) -> #DIV/0! | F44: =F37/(F43*1000) -> #DIV/0! | G44: =G37/(G43*1000) -> #DIV/0! | H44: =H37/(H43*1000) -> #DIV/0! | I44: =I37/(I43*1000) -> #DIV/0! | J44: =J37/(J43*1000) -> #DIV/0! | L44: =L37/(L43*1000) -> #DIV/0! | M44: =M37/(M43*1000) -> #DIV/0! | N44: =N37/(N43*1000) -> #DIV/0! | O44: =O37/(O43*1000) -> #DIV/0! | P44: =P37/(P43*1000) -> #DIV/0! | Q44: =Q37/(Q43*1000) -> #DIV/0! | R44: =R37/(R43*1000) -> #DIV/0! | S44: =S37/(S43*1000) -> #DIV/0! | U44: =U37/(U43*1000) -> #DIV/0! | V44: =V37/(V43*1000) -> #DIV/0! | X44: =X37/(X43*1000) -> #DIV/0! | Y44: =Y37/(Y43*1000) -> #DIV/0!
B46: Interim DPS (CNY) | C46: 半年每股分红（人民币）
...

Sheet Revenue Projection
A1: 收入预测（亿元） | B1: 单位 | C1: 2022A | D1: 2023A | E1: 2024A | F1: 2025A | G1: 2026E | H1: 2027E | I1: 2028E | K1: 1Q25A | L1: 2Q25A | M1: 3Q25A | N1: 4Q25A | O1: 1Q26A | P1: 2Q26A | Q1: 3Q26A | R1: 4Q26E | S1: 重点
A3: 收入拆分
A4: 业务A | B4: 亿元 | G4: =SUM(O4:R4) -> 0 | H4: =H16*H18 -> 0 | I4: =I16*I18 -> 0 | R4: =N4*(1+R5) -> 0 | S4: 来源：<分部收入>；2027E起 = 销量 × 单价（第16–19行）
A5: 业务A增长 | B5: % | D5: =IFERROR(D4/C4-1,"") | E5: =IFERROR(E4/D4-1,"") | F5: =IFERROR(F4/E4-1,"") | G5: =IFERROR(G4/F4-1,"") | H5: =IFERROR(H4/G4-1,"") | I5: =IFERROR(I4/H4-1,"") | O5: =IFERROR(O4/K4-1,"") | P5: =IFERROR(P4/L4-1,"") | Q5: =IFERROR(Q4/M4-1,"") | S5: 来源：<指引/纪要/调研/原模型假设>（原话或数字）；<如何设定>
A6: 业务B | B6: 亿元 | G6: =SUM(O6:R6) -> 0 | H6: =G6*(1+H7) -> 0 | I6: =H6*(1+I7) -> 0 | R6: =N6*(1+R7) -> 0 | S6: 来源：<年报/半年报分部收入；季度来自纪要或卖方拆分>（实际为蓝色）
A7: 业务B增长 | B7: % | D7: =IFERROR(D6/C6-1,"") | E7: =IFERROR(E6/D6-1,"") | F7: =IFERROR(F6/E6-1,"") | G7: =IFERROR(G6/F6-1,"") | O7: =IFERROR(O6/K6-1,"") | P7: =IFERROR(P6/L6-1,"") | Q7: =IFERROR(Q6/M6-1,"") | S7: 来源：<指引/纪要/调研/原模型假设>（原话或数字）；<如何设定>
A8: 业务C | B8: 亿元 | G8: =SUM(O8:R8) -> 0 | H8: =G8*(1+H9) -> 0 | I8: =H8*(1+I9) -> 0 | R8: =N8*(1+R9) -> 0 | S8: 来源：<年报/半年报分部收入；季度来自纪要或卖方拆分>（实际为蓝色）
A9: 业务C增长 | B9: % | D9: =IFERROR(D8/C8-1,"") | E9: =IFERROR(E8/D8-1,"") | F9: =IFERROR(F8/E8-1,"") | G9: =IFERROR(G8/F8-1,"") | O9: =IFERROR(O8/K8-1,"") | P9: =IFERROR(P8/L8-1,"") | Q9: =IFERROR(Q8/M8-1,"") | S9: 来源：<指引/纪要/调研/原模型假设>（原话或数字）；<如何设定>
A10: 其他业务（倒算） | B10: 亿元 | C10: =C12-C4-C6-C8 -> 0 | D10: =D12-D4-D6-D8 -> 0 | E10: =E12-E4-E6-E8 -> 0 | F10: =F12-F4-F6-F8 -> 0 | G10: =SUM(O10:R10) -> 0 | H10: =G10*(1+H11) -> 0 | I10: =H10*(1+I11) -> 0 | K10: =K12-K4-K6-K8 -> 0 | L10: =L12-L4-L6-L8 -> 0 | M10: =M12-M4-M6-M8 -> 0 | N10: =N12-N4-N6-N8 -> 0 | O10: =O12-O4-O6-O8 -> 0 | P10: =P12-P4-P6-P8 -> 0 | Q10: =Q12-Q4-Q6-Q8 -> 0 | R10: =N10*(1+R11) -> 0 | S10: 计算：历史 = 合计 − 分项；预测按增长假设
A11: 其他业务增长 | B11: % | D11: =IFERROR(D10/C10-1,"") | E11: =IFERROR(E10/D10-1,"") | F11: =IFERROR(F10/E10-1,"") | G11: =IFERROR(G10/F10-1,"") | O11: =IFERROR(O10/K10-1,"") | P11: =IFERROR(P10/L10-1,"") | Q11: =IFERROR(Q10/M10-1,"") | S11: 来源：<假设>
A12: 合计 | B12: 亿元 | C12: ='3S'!D4/100000 -> 0 | D12: ='3S'!E4/100000 -> 0 | E12: ='3S'!F4/100000 -> 0 | F12: ='3S'!G4/100000 -> 0 | G12: =G4+G6+G8+G10 -> 0 | H12: =H4+H6+H8+H10 -> 0 | I12: =I4+I6+I8+I10 -> 0 | K12: ='3S'!L4/100000 -> 0 | L12: ='3S'!M4/100000 -> 0 | M12: ='3S'!N4/100000 -> 0 | N12: ='3S'!O4/100000 -> 0 | O12: ='3S'!P4/100000 -> 0 | P12: ='3S'!Q4/100000 -> 0 | Q12: ='3S'!R4/100000 -> 0 | R12: =R4+R6+R8+R10 -> 0 | S12: 计算：历史链接3S营业收入；预测 = 分项加总 → 3S
A13: 合计增长 | B13: % | D13: =IFERROR(D12/C12-1,"") | E13: =IFERROR(E12/D12-1,"") | F13: =IFERROR(F12/E12-1,"") | G13: =IFERROR(G12/F12-1,"") | H13: =IFERROR(H12/G12-1,"") | I13: =IFERROR(I12/H12-1,"") | O13: =IFERROR(O12/K12-1,"") | P13: =IFERROR(P12/L12-1,"") | Q13: =IFERROR(Q12/M12-1,"") | R13: =IFERROR(R12/N12-1,"")
A15: 量价拆分（业务A，可按业务复制）
A16: 销量 | B16: 万台 | H16: =G16*(1+H17) -> 0 | I16: =H16*(1+I17) -> 0 | S16: 来源：Data页 / 年报销量
A17: 销量增长 | B17: % | D17: =IFERROR(D16/C16-1,"") | E17: =IFERROR(E16/D16-1,"") | F17: =IFERROR(F16/E16-1,"") | G17: =IFERROR(G16/F16-1,"") | S17: 来源：<指引/行业数据>
A18: 单价 | B18: 万元/台 | C18: =IFERROR(C4/C16,0) -> 0 | D18: =IFERROR(D4/D16,0) -> 0 | E18: =IFERROR(E4/E16,0) -> 0 | F18: =IFERROR(F4/F16,0) -> 0 | G18: =IFERROR(G4/G16,0) -> 0 | H18: =G18*(1+H19) -> 0 | I18: =H18*(1+I19) -> 0 | S18: 计算：收入 ÷ 销量；预测按单价增长
A19: 单价增长 | B19: % | D19: =IFERROR(D18/C18-1,"") | E19: =IFERROR(E18/D18-1,"") | F19: =IFERROR(F18/E18-1,"") | G19: =IFERROR(G18/F18-1,"") | S19: 来源：<提价/结构>
A21: 毛利率
A22: 业务A毛利率 | B22: % | G22: =F22 -> 0 | H22: =G22 -> 0 | I22: =H22 -> 0 | S22: 来源：<年报分部毛利率>；预测：<管理层说法>
A23: 业务B毛利率 | B23: % | G23: =F23 -> 0 | H23: =G23 -> 0 | I23: =H23 -> 0 | S23: 来源：<年报分部毛利率>；预测：<管理层说法>
A24: 业务C毛利率 | B24: % | G24: =F24 -> 0 | H24: =G24 -> 0 | I24: =H24 -> 0 | S24: 来源：<年报分部毛利率>；预测：<管理层说法>
A25: 其他毛利率 | B25: % | G25: =F25 -> 0 | H25: =G25 -> 0 | I25: =H25 -> 0 | S25: 来源：<年报分部毛利率>；预测：<管理层说法>
A26: 合计毛利率 | B26: % | C26: =IFERROR(C33/C12,"") | D26: =IFERROR(D33/D12,"") | E26: =IFERROR(E33/E12,"") | F26: =IFERROR(F33/F12,"") | G26: =IFERROR(G33/G12,"") | H26: =IFERROR(H33/H12,"") | I26: =IFERROR(I33/I12,"") | K26: =IFERROR(K33/K12,"") | L26: =IFERROR(L33/L12,"") | M26: =IFERROR(M33/M12,"") | N26: =IFERROR(N33/N12,"") | O26: =IFERROR(O33/O12,"") | P26: =IFERROR(P33/P12,"") | Q26: =IFERROR(Q33/Q12,"") | R26: =IFERROR(R33/R12,"")
A28: 毛利
A29: 业务A毛利 | B29: 亿元 | C29: =C4*C22 -> 0 | D29: =D4*D22 -> 0 | E29: =E4*E22 -> 0 | F29: =F4*F22 -> 0 | G29: =G4*G22 -> 0 | H29: =H4*H22 -> 0 | I29: =I4*I22 -> 0
A30: 业务B毛利 | B30: 亿元 | C30: =C6*C23 -> 0 | D30: =D6*D23 -> 0 | E30: =E6*E23 -> 0 | F30: =F6*F23 -> 0 | G30: =G6*G23 -> 0 | H30: =H6*H23 -> 0 | I30: =I6*I23 -> 0
A31: 业务C毛利 | B31: 亿元 | C31: =C8*C24 -> 0 | D31: =D8*D24 -> 0 | E31: =E8*E24 -> 0 | F31: =F8*F24 -> 0 | G31: =G8*G24 -> 0 | H31: =H8*H24 -> 0 | I31: =I8*I24 -> 0
A32: 其他毛利 | B32: 亿元 | C32: =C10*C25 -> 0 | D32: =D10*D25 -> 0 | E32: =E10*E25 -> 0 | F32: =F10*F25 -> 0 | G32: =G10*G25 -> 0 | H32: =H10*H25 -> 0 | I32: =I10*I25 -> 0
A33: 合计毛利 | B33: 亿元 | C33: ='3S'!D7/100000 -> 0 | D33: ='3S'!E7/100000 -> 0 | E33: ='3S'!F7/100000 -> 0 | F33: ='3S'!G7/100000 -> 0 | G33: =SUM(G29:G32) -> 0 | H33: =SUM(H29:H32) -> 0 | I33: =SUM(I29:I32) -> 0 | K33: ='3S'!L7/100000 -> 0 | L33: ='3S'!M7/100000 -> 0 | M33: ='3S'!N7/100000 -> 0 | N33: ='3S'!O7/100000 -> 0 | O33: ='3S'!P7/100000 -> 0 | P33: ='3S'!Q7/100000 -> 0 | Q33: ='3S'!R7/100000 -> 0 | R33: =G33-SUM(O33:Q33) -> 0 | S33: 计算：历史/季度链接3S毛利；预测 = 分项加总；4Q E = 全年 − 前三季度
A34: 差额（实际 − 分项） | B34: 亿元 | C34: =C33-SUM(C29:C32) -> 0 | D34: =D33-SUM(D29:D32) -> 0 | E34: =E33-SUM(E29:E32) -> 0 | F34: =F33-SUM(F29:F32) -> 0 | S34: 计算：历史校准，应接近0
A35: 营业成本合计 | B35: 亿元 | C35: =C12-C33 -> 0 | D35: =D12-D33 -> 0 | E35: =E12-E33 -> 0 | F35: =F12-F33 -> 0 | G35: =G12-G33 -> 0 | H35: =H12-H33 -> 0 | I35: =I12-I33 -> 0 | K35: =K12-K33 -> 0 | L35: =L12-L33 -> 0 | M35: =M12-M33 -> 0 | N35: =N12-N33 -> 0 | O35: =O12-O33 -> 0 | P35: =P12-P33 -> 0 | Q35: =Q12-Q33 -> 0 | R35: =R12-R33 -> 0 | S35: 计算：收入 − 毛利 → 3S营业成本
A37: 利润推测
A38: 期间费用（税金+销售+管理+研发） | B38: 亿元 | C38: =-('3S'!D10+'3S'!D12+'3S'!D14+'3S'!D16)/100000 -> 0 | D38: =-('3S'!E10+'3S'!E12+'3S'!E14+'3S'!E16)/100000 -> 0 | E38: =-('3S'!F10+'3S'!F12+'3S'!F14+'3S'!F16)/100000 -> 0 | F38: =-('3S'!G10+'3S'!G12+'3S'!G14+'3S'!G16)/100000 -> 0 | G38: =-('3S'!H10+'3S'!H12+'3S'!H14+'3S'!H16)/100000 -> #DIV/0! | H38: =-('3S'!I10+'3S'!I12+'3S'!I14+'3S'!I16)/100000 -> #DIV/0! | I38: =-('3S'!J10+'3S'!J12+'3S'!J14+'3S'!J16)/100000 -> #DIV/0! | K38: =-('3S'!L10+'3S'!L12+'3S'!L14+'3S'!L16)/100000 -> 0 | L38: =-('3S'!M10+'3S'!M12+'3S'!M14+'3S'!M16)/100000 -> 0 | M38: =-('3S'!N10+'3S'!N12+'3S'!N14+'3S'!N16)/100000 -> 0 | N38: =-('3S'!O10+'3S'!O12+'3S'!O14+'3S'!O16)/100000 -> 0 | O38: =-('3S'!P10+'3S'!P12+'3S'!P14+'3S'!P16)/100000 -> 0 | P38: =-('3S'!Q10+'3S'!Q12+'3S'!Q14+'3S'!Q16)/100000 -> 0 | Q38: =-('3S'!R10+'3S'!R12+'3S'!R14+'3S'!R16)/100000 -> 0 | R38: =-('3S'!S10+'3S'!S12+'3S'!S14+'3S'!S16)/100000 -> #DIV/0! | S38: 计算：链接3S
A39: 期间费用率 | B39: % | C39: =IFERROR(C38/C12,"") | D39: =IFERROR(D38/D12,"") | E39: =IFERROR(E38/E12,"") | F39: =IFERROR(F38/F12,"") | G39: =IFERROR(G38/G12,"") | H39: =IFERROR(H38/H12,"") | I39: =IFERROR(I38/I12,"") | K39: =IFERROR(K38/K12,"") | L39: =IFERROR(L38/L12,"") | M39: =IFERROR(M38/M12,"") | N39: =IFERROR(N38/N12,"") | O39: =IFERROR(O38/O12,"") | P39: =IFERROR(P38/P12,"") | Q39: =IFERROR(Q38/Q12,"") | R39: =IFERROR(R38/R12,"")
A40: 归母净利润 | B40: 亿元 | C40: ='3S'!D37/100000 -> 0 | D40: ='3S'!E37/100000 -> 0 | E40: ='3S'!F37/100000 -> 0 | F40: ='3S'!G37/100000 -> 0 | G40: ='3S'!H37/100000 -> #DIV/0! | H40: ='3S'!I37/100000 -> #DIV/0! | I40: ='3S'!J37/100000 -> #DIV/0! | K40: ='3S'!L37/100000 -> 0 | L40: ='3S'!M37/100000 -> 0 | M40: ='3S'!N37/100000 -> 0 | N40: ='3S'!O37/100000 -> 0 | O40: ='3S'!P37/100000 -> 0 | P40: ='3S'!Q37/100000 -> 0 | Q40: ='3S'!R37/100000 -> 0 | R40: ='3S'!S37/100000 -> #DIV/0! | S40: 计算：链接3S
A41: 归母净利润增长 | B41: % | D41: =IFERROR(D40/C40-1,"") | E41: =IFERROR(E40/D40-1,"") | F41: =IFERROR(F40/E40-1,"") | G41: =IFERROR(G40/F40-1,"") | H41: =IFERROR(H40/G40-1,"") | I41: =IFERROR(I40/H40-1,"")
A42: 参考：一致预期收入 | B42: 亿元 | S42: 来源：FactSet consensus_fixed（日期、家数）
A43: 参考：一致预期归母净利润 | B43: 亿元 | S43: 来源：FactSet consensus_fixed（日期、家数）；一致预期全年 − 前三季度 = 隐含四季度

Sheet Data
A1: <公司>｜销量数据（月度加总） | B1: 单位 | C1: 2023 | D1: 2024 | E1: 2025 | G1: 1Q25 | H1: 2Q25 | I1: 3Q25 | J1: 4Q25 | K1: 1Q26 | L1: 2Q26 | M1: 3Q26 | O1: 9M25 | P1: 9M26
A3: 来源：<月度跟踪表/券商数据库/公司公告>。季度、年度 = 月度加总；蓝字 = 源数据，黑字 = 公式，灰字 = 同比/占比。只放销量，不放收入和价格。
A5: 一、公司销量
A6: 整体 | B6: 台 | O6: =SUM(G6:I6) -> 0 | P6: =SUM(K6:M6) -> 0
A7: 同比 | B7: % | D7: =IFERROR(D6/C6-1,"") | E7: =IFERROR(E6/D6-1,"") | K7: =IFERROR(K6/G6-1,"") | L7: =IFERROR(L6/H6-1,"") | M7: =IFERROR(M6/I6-1,"") | P7: =IFERROR(P6/O6-1,"")
A8: 出口 | B8: 台 | O8: =SUM(G8:I8) -> 0 | P8: =SUM(K8:M8) -> 0
A9: 同比 | B9: % | D9: =IFERROR(D8/C8-1,"") | E9: =IFERROR(E8/D8-1,"") | K9: =IFERROR(K8/G8-1,"") | L9: =IFERROR(L8/H8-1,"") | M9: =IFERROR(M8/I8-1,"") | P9: =IFERROR(P8/O8-1,"")
A10: 内销 | B10: 台 | C10: =IF(C6="","",C6-C8) | D10: =IF(D6="","",D6-D8) | E10: =IF(E6="","",E6-E8) | G10: =IF(G6="","",G6-G8) | H10: =IF(H6="","",H6-H8) | I10: =IF(I6="","",I6-I8) | J10: =IF(J6="","",J6-J8) | K10: =IF(K6="","",K6-K8) | L10: =IF(L6="","",L6-L8) | M10: =IF(M6="","",M6-M8) | O10: =IF(O6="","",O6-O8) -> 0 | P10: =IF(P6="","",P6-P8) -> 0
A11: 出口占比 | B11: % | C11: =IFERROR(C8/C6,"") | D11: =IFERROR(D8/D6,"") | E11: =IFERROR(E8/E6,"") | G11: =IFERROR(G8/G6,"") | H11: =IFERROR(H8/H6,"") | I11: =IFERROR(I8/I6,"") | J11: =IFERROR(J8/J6,"") | K11: =IFERROR(K8/K6,"") | L11: =IFERROR(L8/L6,"") | M11: =IFERROR(M8/M6,"") | O11: =IFERROR(O8/O6,"") | P11: =IFERROR(P8/P6,"")
A13: 二、行业
A14: 行业整体 | B14: 台 | O14: =SUM(G14:I14) -> 0 | P14: =SUM(K14:M14) -> 0
A15: 同比 | B15: % | D15: =IFERROR(D14/C14-1,"") | E15: =IFERROR(E14/D14-1,"") | K15: =IFERROR(K14/G14-1,"") | L15: =IFERROR(L14/H14-1,"") | M15: =IFERROR(M14/I14-1,"") | P15: =IFERROR(P14/O14-1,"")
A16: 公司份额 | B16: % | C16: =IFERROR(C6/C14,"") | D16: =IFERROR(D6/D14,"") | E16: =IFERROR(E6/E14,"") | G16: =IFERROR(G6/G14,"") | H16: =IFERROR(H6/H14,"") | I16: =IFERROR(I6/I14,"") | J16: =IFERROR(J6/J14,"") | K16: =IFERROR(K6/K14,"") | L16: =IFERROR(L6/L14,"") | M16: =IFERROR(M6/M14,"") | O16: =IFERROR(O6/O14,"") | P16: =IFERROR(P6/P14,"")

Sheet Guidance
B2: <公司> <期间> 交流核心指引（YYYY-MM-DD）
B3: 来源：<纪要文件名>（纪要MMDD）；同场多份纪要逐条注明出处；数字核对公司公告
C4: 来源
B5: <板块：销量 / 毛利率 / 费用 / 分红 / 明年展望>
B6: 1. <一句话一条指引，带数字和管理层原话的限定词> | C6: 纪要MMDD

Sheet 问题
A1: <公司>｜管理层问题（<期间>后，YYYY-MM-DD）
A2: 筛选：已剔除<纪要日期>交流已回答的问题（<列出>）；按对下一年利润的影响排序；问方向/对比，不问具体数字。
A4: # | B4: 主题 | C4: 问题 | D4: 模型当前假设 | E4: 怎么解读答案 → 调整哪个假设 | F4: 回答记录
A5: 1 | C5: <一句口语化的问题，最多两问> | D5: <模型当前数字，及卖方数字> | E5: <回答A → 维持；回答B → 调整第X行，约±X亿>
A6: 2
A7: 3
A8: 4
A9: 5

Sheet 投资逻辑
B1: <公司>（<代码>）｜投资逻辑
B2: 数字均链接3S / Revenue Projection；股价为FactSet <日期>收盘；紫色 = 可改输入。
B4: 一、为什么投资
B5: 1. <驱动因素 + 模型中的数字>
B6: 2. <驱动因素 + 模型中的数字>
B7: 3. <驱动因素 + 模型中的数字>
B8: 4. <驱动因素 + 模型中的数字>
B9: 5. <驱动因素 + 模型中的数字>
B11: 二、目标价与上涨空间 | C11: 数值 | D11: 说明
B12: 当前股价（元） | D12: FactSet <日期>收盘
B13: 2026E EPS（元） | C13: ='3S'!H44 -> #DIV/0! | D13: 3S：前三季度实际 + 4Q E
B14: 2027E EPS（元） | C14: ='3S'!I44 -> #DIV/0! | D14: 3S 下一年E
B15: 目标P/E（2027E） | C15: ='3S'!I61 -> #DIV/0! | D15: 默认 = 3S同业平均P/E（第61行）；可手填倍数
B16: 目标价（元） | C16: =C15*C14 -> #DIV/0! | D16: 目标P/E × 2027E EPS
B17: 上涨空间 | C17: =C16/C12-1 -> #DIV/0! | D17: 目标价 / 现价 − 1
B18: 2026E 每股分红（元） | C18: ='3S'!H48 -> #DIV/0! | D18: 管理层分红指引，或EPS × 分红率（3S第50行）
B19: 2026E 股息率 | C19: =C18/C12 -> #DIV/0!
B20: 2027E 每股分红（元） | C20: ='3S'!I48 -> #DIV/0! | D20: 3S第50行分红率
B21: 2027E 股息率 | C21: =C20/C12 -> #DIV/0!
B22: 总回报（上涨空间 + 2026E股息率） | C22: =C17+C19 -> #DIV/0!
B23: 当前P/E 2026E | C23: =C12/C13 -> #DIV/0!
B24: 当前P/E 2027E | C24: =C12/C14 -> #DIV/0!
B26: 参考：同业P/E 2026E（现价） | C26: ='3S'!H61 -> #DIV/0! | D26: 链接3S第61行（现价 ÷ FactSet一致预期EPS）
B27: 参考：同业P/E 2027E（现价） | C27: ='3S'!I61 -> #DIV/0! | D27: 链接3S第61行
B28: 参考：一致预期目标价（元） | D28: FactSet均值，区间<低–高>
B29: 参考：一致预期归母2026E（亿元） | D29: <家数>；最近修改日期；隐含剩余季度
B30: 参考：模型归母2026E（亿元） | C30: ='3S'!H37/100000 -> #DIV/0!
B31: 参考：一致预期归母2027E（亿元）
B32: 参考：模型归母2027E（亿元） | C32: ='3S'!I37/100000 -> #DIV/0!
B33: 参考：按一致预期EPS的目标价（元） | C33: =C15*C31/('3S'!I43/100) -> #DIV/0! | D33: 目标P/E × 一致预期2027E EPS
B35: 三、什么会证伪我们的逻辑
B36: 1. <可观察指标>低于/高于<阈值> → <对模型的影响，约±X亿>
B37: 2. <可观察指标>低于/高于<阈值> → <对模型的影响，约±X亿>
B38: 3. <可观察指标>低于/高于<阈值> → <对模型的影响，约±X亿>
B39: 4. <可观察指标>低于/高于<阈值> → <对模型的影响，约±X亿>
B40: 5. <可观察指标>低于/高于<阈值> → <对模型的影响，约±X亿>
B42: 四、历史估值：5年前瞻P/E区间 | C42: 数值 | D42: 说明
B43: 均值 / 标准差 | C43: =TEXT(估值区间!C5,"0.0x")&" / "&TEXT(估值区间!C6,"0.0x") -> #DIV/0! | D43: FactSet一致预期口径月份（注明缺口和单家预测的月份）
B44: −2SD / −1SD / +1SD / +2SD | C44: =TEXT(估值区间!C10,"0.0x")&" / "&TEXT(估值区间!C8,"0.0x")&" / "&TEXT(估值区间!C7,"0.0x")&" / "&TEXT(估值区间!C9,"0.0x") -> #DIV/0!
B45: 现价前瞻P/E：一致预期EPS | C45: =估值区间!C15 -> #DIV/0! | D45: ="位置 "&TEXT(估值区间!C17,"+0.0;-0.0")&"SD" -> #DIV/0!
...

Sheet 估值区间
A1: <公司>｜5年前瞻市盈率区间（月度）
A2: 来源：FactSet月末收盘价；前瞻EPS = FactSet一致预期NTM EPS（有覆盖的月份），无覆盖月份用实际未来12个月EPS（季度EPS按月摊）
A4: 统计区间（一致预期口径月份数） | C4: =COUNT(F21:F81) -> 0 | F4: 参考：5年全部月份（含实际口径）
A5: 均值 | C5: =_xlfn.AGGREGATE(1,6,F21:F81) -> #DIV/0! | F5: 均值 | G5: =AVERAGE(E21:E81) -> #DIV/0!
A6: 标准差（SD） | C6: =_xlfn.AGGREGATE(8,6,F21:F81) -> #DIV/0! | F6: SD | G6: =_xlfn.STDEV.P(E21:E81) -> #DIV/0!
A7: +1SD | C7: =C5+C6 -> #DIV/0! | F7: 月份数 | G7: =COUNT(E21:E81) -> 0
A8: −1SD | C8: =C5-C6 -> #DIV/0!
A9: +2SD | C9: =C5+2*C6 -> #DIV/0!
A10: −2SD | C10: =C5-2*C6 -> #DIV/0!
A12: 现价（元） | C12: =投资逻辑!C12 -> 0 | D12: <日期>收盘
A13: 一致预期NTM EPS（元） | C13: =C81 -> 0 | D13: FactSet <月份>
A14: 模型NTM EPS（元） | C14: ='3S'!S44*2/3+'3S'!I44*10/12 -> #DIV/0! | D14: = 4Q26E EPS × 2/3 + 2027E EPS × 10/12（2026年11月–2027年10月）
A15: 前瞻P/E：一致预期口径 | C15: =C12/C13 -> #DIV/0!
A16: 前瞻P/E：模型口径 | C16: =C12/C14 -> #DIV/0!
A17: 位置：一致预期口径（SD） | C17: =(C15-C5)/C6 -> #DIV/0! | D17: 0 = 均值；+1 = +1SD
A18: 位置：模型口径（SD） | C18: =(C16-C5)/C6 -> #DIV/0!
A20: 月份 | B20: 股价（元） | C20: 前瞻EPS（元） | D20: 口径 | E20: 前瞻P/E | F20: P/E（一致预期口径） | G20: P/E（实际口径，参考） | H20: 均值 | I20: +1SD | J20: −1SD | K20: +2SD | L20: −2SD | M20: P/E（模型EPS，仅现价）
E21: =B21/C21 -> #DIV/0! | F21: =IF(LEFT(D21,4)="一致预期",E21,NA()) -> #N/A | G21: =IF(ISNUMBER(SEARCH("实际",D21)),E21,NA()) -> #N/A | H21: =$C$5 -> #DIV/0! | I21: =$C$7 -> #DIV/0! | J21: =$C$8 -> #DIV/0! | K21: =$C$9 -> #DIV/0! | L21: =$C$10 -> #DIV/0! | M21: =IF(ROW()=81,$C$16,NA()) -> #N/A
E22: =B22/C22 -> #DIV/0! | F22: =IF(LEFT(D22,4)="一致预期",E22,NA()) -> #N/A | G22: =IF(ISNUMBER(SEARCH("实际",D22)),E22,NA()) -> #N/A | H22: =$C$5 -> #DIV/0! | I22: =$C$7 -> #DIV/0! | J22: =$C$8 -> #DIV/0! | K22: =$C$9 -> #DIV/0! | L22: =$C$10 -> #DIV/0! | M22: =IF(ROW()=81,$C$16,NA()) -> #N/A
E23: =B23/C23 -> #DIV/0! | F23: =IF(LEFT(D23,4)="一致预期",E23,NA()) -> #N/A | G23: =IF(ISNUMBER(SEARCH("实际",D23)),E23,NA()) -> #N/A | H23: =$C$5 -> #DIV/0! | I23: =$C$7 -> #DIV/0! | J23: =$C$8 -> #DIV/0! | K23: =$C$9 -> #DIV/0! | L23: =$C$10 -> #DIV/0! | M23: =IF(ROW()=81,$C$16,NA()) -> #N/A
E24: =B24/C24 -> #DIV/0! | F24: =IF(LEFT(D24,4)="一致预期",E24,NA()) -> #N/A | G24: =IF(ISNUMBER(SEARCH("实际",D24)),E24,NA()) -> #N/A | H24: =$C$5 -> #DIV/0! | I24: =$C$7 -> #DIV/0! | J24: =$C$8 -> #DIV/0! | K24: =$C$9 -> #DIV/0! | L24: =$C$10 -> #DIV/0! | M24: =IF(ROW()=81,$C$16,NA()) -> #N/A
E25: =B25/C25 -> #DIV/0! | F25: =IF(LEFT(D25,4)="一致预期",E25,NA()) -> #N/A | G25: =IF(ISNUMBER(SEARCH("实际",D25)),E25,NA()) -> #N/A | H25: =$C$5 -> #DIV/0! | I25: =$C$7 -> #DIV/0! | J25: =$C$8 -> #DIV/0! | K25: =$C$9 -> #DIV/0! | L25: =$C$10 -> #DIV/0! | M25: =IF(ROW()=81,$C$16,NA()) -> #N/A
E26: =B26/C26 -> #DIV/0! | F26: =IF(LEFT(D26,4)="一致预期",E26,NA()) -> #N/A | G26: =IF(ISNUMBER(SEARCH("实际",D26)),E26,NA()) -> #N/A | H26: =$C$5 -> #DIV/0! | I26: =$C$7 -> #DIV/0! | J26: =$C$8 -> #DIV/0! | K26: =$C$9 -> #DIV/0! | L26: =$C$10 -> #DIV/0! | M26: =IF(ROW()=81,$C$16,NA()) -> #N/A
E27: =B27/C27 -> #DIV/0! | F27: =IF(LEFT(D27,4)="一致预期",E27,NA()) -> #N/A | G27: =IF(ISNUMBER(SEARCH("实际",D27)),E27,NA()) -> #N/A | H27: =$C$5 -> #DIV/0! | I27: =$C$7 -> #DIV/0! | J27: =$C$8 -> #DIV/0! | K27: =$C$9 -> #DIV/0! | L27: =$C$10 -> #DIV/0! | M27: =IF(ROW()=81,$C$16,NA()) -> #N/A
E28: =B28/C28 -> #DIV/0! | F28: =IF(LEFT(D28,4)="一致预期",E28,NA()) -> #N/A | G28: =IF(ISNUMBER(SEARCH("实际",D28)),E28,NA()) -> #N/A | H28: =$C$5 -> #DIV/0! | I28: =$C$7 -> #DIV/0! | J28: =$C$8 -> #DIV/0! | K28: =$C$9 -> #DIV/0! | L28: =$C$10 -> #DIV/0! | M28: =IF(ROW()=81,$C$16,NA()) -> #N/A
E29: =B29/C29 -> #DIV/0! | F29: =IF(LEFT(D29,4)="一致预期",E29,NA()) -> #N/A | G29: =IF(ISNUMBER(SEARCH("实际",D29)),E29,NA()) -> #N/A | H29: =$C$5 -> #DIV/0! | I29: =$C$7 -> #DIV/0! | J29: =$C$8 -> #DIV/0! | K29: =$C$9 -> #DIV/0! | L29: =$C$10 -> #DIV/0! | M29: =IF(ROW()=81,$C$16,NA()) -> #N/A
E30: =B30/C30 -> #DIV/0! | F30: =IF(LEFT(D30,4)="一致预期",E30,NA()) -> #N/A | G30: =IF(ISNUMBER(SEARCH("实际",D30)),E30,NA()) -> #N/A | H30: =$C$5 -> #DIV/0! | I30: =$C$7 -> #DIV/0! | J30: =$C$8 -> #DIV/0! | K30: =$C$9 -> #DIV/0! | L30: =$C$10 -> #DIV/0! | M30: =IF(ROW()=81,$C$16,NA()) -> #N/A
E31: =B31/C31 -> #DIV/0! | F31: =IF(LEFT(D31,4)="一致预期",E31,NA()) -> #N/A | G31: =IF(ISNUMBER(SEARCH("实际",D31)),E31,NA()) -> #N/A | H31: =$C$5 -> #DIV/0! | I31: =$C$7 -> #DIV/0! | J31: =$C$8 -> #DIV/0! | K31: =$C$9 -> #DIV/0! | L31: =$C$10 -> #DIV/0! | M31: =IF(ROW()=81,$C$16,NA()) -> #N/A
E32: =B32/C32 -> #DIV/0! | F32: =IF(LEFT(D32,4)="一致预期",E32,NA()) -> #N/A | G32: =IF(ISNUMBER(SEARCH("实际",D32)),E32,NA()) -> #N/A | H32: =$C$5 -> #DIV/0! | I32: =$C$7 -> #DIV/0! | J32: =$C$8 -> #DIV/0! | K32: =$C$9 -> #DIV/0! | L32: =$C$10 -> #DIV/0! | M32: =IF(ROW()=81,$C$16,NA()) -> #N/A
... E81: =B81/C81 -> #DIV/0! | F81: =IF(LEFT(D81,4)="一致预期",E81,NA()) -> #N/A | G81: =IF(ISNUMBER(SEARCH("实际",D81)),E81,NA()) -> #N/A | H81: =$C$5 -> #DIV/0! | I81: =$C$7 -> #DIV/0! | J81: =$C$8 -> #DIV/0! | K81: =$C$9 -> #DIV/0! | L81: =$C$10 -> #DIV/0! | M81: =IF(ROW()=81,$C$16,NA()) -> #DIV/0!
